Workbook

Sheet Summary 
A1: AR SUMMARY
A2: STATUS | B2: AMOUNT | C2: NO OF CLAIMS
A3: Claim Paid - EFT | B3: =SUMIFS('Level 1'!J5:J1200, 'Level 1'!M5:M1200,Table1[[#This Row],[Select Status]]) -> 62214.8 | C3: =COUNTIFS('Level 1'!M5:M1200,Table1[[#This Row],[Select Status]]) -> 133
A4: Claim Paid - CHK | B4: =SUMIFS('Level 1'!J5:J1200, 'Level 1'!M5:M1200,Table1[[#This Row],[Select Status]]) -> 19769.6 | C4: =COUNTIFS('Level 1'!M5:M1200,Table1[[#This Row],[Select Status]]) -> 43
A5: Claim in Process | B5: =SUMIFS('Level 1'!J5:J1200, 'Level 1'!M5:M1200,Table1[[#This Row],[Select Status]]) -> 88.8 | C5: =COUNTIFS('Level 1'!M5:M1200,Table1[[#This Row],[Select Status]]) -> 1
A6: Frequency Denial | B6: =SUMIFS('Level 1'!J5:J1200, 'Level 1'!M5:M1200,Table1[[#This Row],[Select Status]]) -> 670.4 | C6: =COUNTIFS('Level 1'!M5:M1200,Table1[[#This Row],[Select Status]]) -> 5
A7: Maxed out Denial | B7: =SUMIFS('Level 1'!J5:J1200, 'Level 1'!M5:M1200,Table1[[#This Row],[Select Status]]) -> 288.8 | C7: =COUNTIFS('Level 1'!M5:M1200,Table1[[#This Row],[Select Status]]) -> 2
A8: Not Covered | B8: =SUMIFS('Level 1'!J5:J1200, 'Level 1'!M5:M1200,Table1[[#This Row],[Select Status]]) -> 5719.6 | C8: =COUNTIFS('Level 1'!M5:M1200,Table1[[#This Row],[Select Status]]) -> 15
A9: Miss Tth Clause Denial | B9: =SUMIFS('Level 1'!J5:J1200, 'Level 1'!M5:M1200,Table1[[#This Row],[Select Status]]) -> 0 | C9: =COUNTIFS('Level 1'!M5:M1200,Table1[[#This Row],[Select Status]]) -> 0
A10: Dup Submission | B10: =SUMIFS('Level 1'!J5:J1200, 'Level 1'!M5:M1200,Table1[[#This Row],[Select Status]]) -> 81.2 | C10: =COUNTIFS('Level 1'!M5:M1200,Table1[[#This Row],[Select Status]]) -> 2
A11: Waiting Pd Denial | B11: =SUMIFS('Level 1'!J5:J1200, 'Level 1'!M5:M1200,Table1[[#This Row],[Select Status]]) -> 0 | C11: =COUNTIFS('Level 1'!M5:M1200,Table1[[#This Row],[Select Status]]) -> 0
A12: Pr Paid Max | B12: =SUMIFS('Level 1'!J5:J1200, 'Level 1'!M5:M1200,Table1[[#This Row],[Select Status]]) -> 1114 | C12: =COUNTIFS('Level 1'!M5:M1200,Table1[[#This Row],[Select Status]]) -> 4
A13: Invd Proc Code | B13: =SUMIFS('Level 1'!J5:J1200, 'Level 1'!M5:M1200,Table1[[#This Row],[Select Status]]) -> 0 | C13: =COUNTIFS('Level 1'!M5:M1200,Table1[[#This Row],[Select Status]]) -> 0
A14: SRP Hist Dts Denial | B14: =SUMIFS('Level 1'!J5:J1200, 'Level 1'!M5:M1200,Table1[[#This Row],[Select Status]]) -> 0 | C14: =COUNTIFS('Level 1'!M5:M1200,Table1[[#This Row],[Select Status]]) -> 0
A15: Init Placement Dt Denial | B15: =SUMIFS('Level 1'!J5:J1200, 'Level 1'!M5:M1200,Table1[[#This Row],[Select Status]]) -> 0 | C15: =COUNTIFS('Level 1'!M5:M1200,Table1[[#This Row],[Select Status]]) -> 0
A16: TFL Denial | B16: =SUMIFS('Level 1'!J5:J1200, 'Level 1'!M5:M1200,Table1[[#This Row],[Select Status]]) -> 1515.6 | C16: =COUNTIFS('Level 1'!M5:M1200,Table1[[#This Row],[Select Status]]) -> 1
A17: Age Limit Denial | B17: =SUMIFS('Level 1'!J5:J1200, 'Level 1'!M5:M1200,Table1[[#This Row],[Select Status]]) -> 0 | C17: =COUNTIFS('Level 1'!M5:M1200,Table1[[#This Row],[Select Status]]) -> 0
A18: Miss Attach Denial | B18: =SUMIFS('Level 1'!J5:J1200, 'Level 1'!M5:M1200,Table1[[#This Row],[Select Status]]) -> 2794.8 | C18: =COUNTIFS('Level 1'!M5:M1200,Table1[[#This Row],[Select Status]]) -> 1
A19: Nd More Info | B19: =SUMIFS('Level 1'!J5:J1200, 'Level 1'!M5:M1200,Table1[[#This Row],[Select Status]]) -> 13999.2 | C19: =COUNTIFS('Level 1'!M5:M1200,Table1[[#This Row],[Select Status]]) -> 32
A20: Claim not on File | B20: =SUMIFS('Level 1'!J5:J1200, 'Level 1'!M5:M1200,Table1[[#This Row],[Select Status]]) -> 16996.4 | C20: =COUNTIFS('Level 1'!M5:M1200,Table1[[#This Row],[Select Status]]) -> 39
A21: No Active Policy | B21: =SUMIFS('Level 1'!J5:J1200, 'Level 1'!M5:M1200,Table1[[#This Row],[Select Status]]) -> 4389.6 | C21: =COUNTIFS('Level 1'!M5:M1200,Table1[[#This Row],[Select Status]]) -> 4
A22: Claim Partially Paid - EFT | B22: =SUMIFS('Level 1'!J5:J1200, 'Level 1'!M5:M1200,Table1[[#This Row],[Select Status]]) -> 991.2 | C22: =COUNTIFS('Level 1'!M5:M1200,Table1[[#This Row],[Select Status]]) -> 3
A23: Claim Partially Paid - CHK | B23: =SUMIFS('Level 1'!J5:J1200, 'Level 1'!M5:M1200,Table1[[#This Row],[Select Status]]) -> 332.4 | C23: =COUNTIFS('Level 1'!M5:M1200,Table1[[#This Row],[Select Status]]) -> 2
A24: Patient Not Found | B24: =SUMIFS('Level 1'!J5:J1200, 'Level 1'!M5:M1200,Table1[[#This Row],[Select Status]]) -> 0 | C24: =COUNTIFS('Level 1'!M5:M1200,Table1[[#This Row],[Select Status]]) -> 0
A25: Other | B25: =SUMIFS('Level 1'!J5:J1200, 'Level 1'!M5:M1200,Table1[[#This Row],[Select Status]]) -> 4026.8 | C25: =COUNTIFS('Level 1'!M6:M1201,Table1[[#This Row],[Select Status]]) -> 10
A26: To be Followed up | B26: ='Level 1'!G3 -> 311311.8 | C26: ='Level 1'!H3 -> 768
A27: Total | B27: =SUM(B3:B26) -> 446305 | C27: =SUM(C3:C26) -> 1065

Sheet Level 1
A1: AR REPORT | F1: OUTSTANDING | G1: =SUM(J5:J1200) -> 440954.6 | H1: =COUNTIF(A5:A1200,"*") -> 1048 | I1: Claims
A2: CLIENT NAME | C2: Sweet Smiles | F2: COMPLETED | G2: =SUM('Summary '!B3:B21) -> 129642.8 | H2: =COUNTIF(AG5:AG1200,"Follow-Up Complete") -> 280 | I2: Claims
A3: Report Date | C3: 44670 | F3: NOT COMPLETED | G3: =SUM(G1-G2) -> 311311.8 | H3: =SUM(H1-H2) -> 768 | I3: Claims | AE3: Level 1
A4: INS Company | B4: INS Ph No | C4: SUBSCRIBER NAME | D4: SUB ID | E4: Patient ID | F4: PATIENT NAME | G4: DOB | H4: DOS | I4: SENT | J4: TOTAL | K4: DAYS | L4: Location | M4: Claim Status | N4: Note | O4: Q1 | Q4: Q2 | S4: Q3 | U4: Q4 | W4: Q5 | Y4: Claim Action | Z4: Additional Notes: | AB4: NXT FLUP DT | AC4: EOB DL | AD4: Team worked | AE4: Worked By | AF4: Worked Dt | AG4: Follow-Up Status
A5: =Data!K4 -> Aetna | B5: =Data!L4 -> 8004517715 | C5: =Data!D4 -> Passehl , Kayla | D5: =Data!F4 -> W237205096 | E5: =Data!B4 -> 9200 | F5: =Data!A4 -> Passehl , Kayla | G5: =Data!C4 -> 7/30/1991 | H5: =Data!H4 -> 44635 | I5: =Data!I4 -> 3/24/2022 | J5: =Data!J4 -> 292.4 | K5: =TODAY()-I5 -> 56 | L5: =Data!M4 -> 0 | M5: Select Status | N5: =VLOOKUP(M5,Table1[#All],3,FALSE) -> Note | O5: =VLOOKUP(M5,Table1[#All],4,FALSE) -> Q1 | Q5: =VLOOKUP(M5,Table1[#All],5,FALSE) -> Q2 | S5: =VLOOKUP(M5,Table1[#All],6,FALSE) -> Q3 | U5: =VLOOKUP(M5,Table1[#All],7,FALSE) -> Q4 | W5: =VLOOKUP(M5,Table1[#All],8,FALSE) -> Q5 | Y5: =VLOOKUP(M5,Table1[#All],2,FALSE) -> Action | Z5: =VLOOKUP(M5,Table1[#All],9,FALSE) -> Additional Notes: | AC5: Select | AD5: Select | AG5: Select
A6: =Data!K5 -> Ameritas | B6: =Data!L5 -> 8006592223 | C6: =Data!D5 -> Brown, Isabella | D6: =Data!F5 -> 016776290 | E6: =Data!B5 -> 7412 | F6: =Data!A5 -> Brown, Isabella | G6: =Data!C5 -> 3/15/1962 | H6: =Data!H5 -> 44470 | I6: =Data!I5 -> 10/7/2021 | J6: =Data!J5 -> 1036.8 | K6: =TODAY()-I6 -> 224 | L6: =Data!M5 -> 0 | M6: CLAIM PAID - CHK | N6: =VLOOKUP(M6,Table1[#All],3,FALSE) -> Claim Paid by Check; | O6: =VLOOKUP(M6,Table1[#All],4,FALSE) -> Issue Date: | P6: 44484 | Q6: =VLOOKUP(M6,Table1[#All],5,FALSE) -> CHK# | R6: 237237308 | S6: =VLOOKUP(M6,Table1[#All],6,FALSE) -> Bulk/Sep: | T6: Single | U6: =VLOOKUP(M6,Table1[#All],7,FALSE) -> Call Ref#: | V6: 2070 | W6: =VLOOKUP(M6,Table1[#All],8,FALSE) -> Cust Rep: | X6: Poni | Y6: =VLOOKUP(M6,Table1[#All],2,FALSE) -> Task Cashed Chk Queue | Z6: =VLOOKUP(M6,Table1[#All],9,FALSE) -> Additional Notes: | AA6: Rep states that clm #043444672190, paid amt $702.40, Its is a V.C.C payment and the draft number #237237308, patient responsibility is 303.60. cashed dt 10/26/2021. | AB6: TASK CREATED | AC6: YES | AD6: V Team | AE6: MU | AF6: 44627 | AG6: Follow-Up Complete
A7: =Data!K6 -> Anthem | B7: =Data!L6 -> 8447291565 | C7: =Data!D6 -> Thom, Keri | D7: =Data!F6 -> GQP130W03886 | E7: =Data!B6 -> 9330 | F7: =Data!A6 -> Thom, Keri | G7: =Data!C6 -> 8/14/2006 | H7: =Data!H6 -> 44642 | I7: =Data!I6 -> 3/25/2022 | J7: =Data!J6 -> 294.8 | K7: =TODAY()-I7 -> 55 | L7: =Data!M6 -> 0 | M7: Select Status | N7: =VLOOKUP(M7,Table1[#All],3,FALSE) -> Note | O7: =VLOOKUP(M7,Table1[#All],4,FALSE) -> Q1 | Q7: =VLOOKUP(M7,Table1[#All],5,FALSE) -> Q2 | S7: =VLOOKUP(M7,Table1[#All],6,FALSE) -> Q3 | U7: =VLOOKUP(M7,Table1[#All],7,FALSE) -> Q4 | W7: =VLOOKUP(M7,Table1[#All],8,FALSE) -> Q5 | Y7: =VLOOKUP(M7,Table1[#All],2,FALSE) -> Action | Z7: =VLOOKUP(M7,Table1[#All],9,FALSE) -> Additional Notes: | AC7: Select | AD7: Select | AG7: Select
A8: =Data!K7 -> Anthem | B8: =Data!L7 -> 8447291565 | C8: =Data!D7 -> Wricks, Derrishia | D8: =Data!F7 -> 201W03443 | E8: =Data!B7 -> 4527 | F8: =Data!A7 -> Wricks, Derrishia | G8: =Data!C7 -> 9/28/1993 | H8: =Data!H7 -> 44545 | I8: =Data!I7 -> 2/10/2022 | J8: =Data!J7 -> 266 | K8: =TODAY()-I8 -> 98 | L8: =Data!M7 -> 0 | M8: CNOF Active | N8: =VLOOKUP(M8,Table1[#All],3,FALSE) -> Claim not on file. Patient is active ; | O8: =VLOOKUP(M8,Table1[#All],4,FALSE) -> Payor ID & Address: | P8: CB950 | Q8: =VLOOKUP(M8,Table1[#All],5,FALSE) -> Fax # (If Fax Yes): | S8: =VLOOKUP(M8,Table1[#All],6,FALSE) -> TFL in Mnths: | T8: 12Months from Dos | U8: =VLOOKUP(M8,Table1[#All],7,FALSE) -> Call Ref#: | V8: LEANDRO | W8: =VLOOKUP(M8,Table1[#All],8,FALSE) -> Cust Rep: | X8: 8719609 | Y8: =VLOOKUP(M8,Table1[#All],2,FALSE) -> Task Sub Pending Claims Queue | Z8: =VLOOKUP(M8,Table1[#All],9,FALSE) -> Additional Notes: | AA8: CNOF - Active | AB8: NV pending | AC8: NO | AD8: V Team | AE8: SF | AF8: 44692 | AG8: Follow-Up Complete
A9: =Data!K8 -> Anthem | B9: =Data!L8 -> 8447291565 | C9: =Data!D8 -> Allen, Janiyah | D9: =Data!F8 -> 201W03443 | E9: =Data!B8 -> 8543 | F9: =Data!A8 -> Allen, Janiyah | G9: =Data!C8 -> 9/28/1993 | H9: =Data!H8 -> 44545 | I9: =Data!I8 -> 2/11/2022 | J9: =Data!J8 -> 307.2 | K9: =TODAY()-I9 -> 97 | L9: =Data!M8 -> 0 | M9: CNOF Active | N9: =VLOOKUP(M9,Table1[#All],3,FALSE) -> Claim not on file. Patient is active ; | O9: =VLOOKUP(M9,Table1[#All],4,FALSE) -> Payor ID & Address: | P9: CB950 | Q9: =VLOOKUP(M9,Table1[#All],5,FALSE) -> Fax # (If Fax Yes): | S9: =VLOOKUP(M9,Table1[#All],6,FALSE) -> TFL in Mnths: | T9: 12 Months from Dos | U9: =VLOOKUP(M9,Table1[#All],7,FALSE) -> Call Ref#: | V9: 87214304 | W9: =VLOOKUP(M9,Table1[#All],8,FALSE) -> Cust Rep: | X9: CELLE | Y9: =VLOOKUP(M9,Table1[#All],2,FALSE) -> Task Sub Pending Claims Queue | Z9: =VLOOKUP(M9,Table1[#All],9,FALSE) -> Additional Notes: | AA9: CNOF - Active. | AB9: NV pending | AC9: NO | AD9: V Team | AE9: SF | AF9: 44693 | AG9: Follow-Up Complete
A10: =Data!K9 -> Cigna | B10: =Data!L9 -> 8002446224 | C10: =Data!D9 -> Sullivan, Jessica | D10: =Data!F9 -> U47262786 | E10: =Data!B9 -> 9345 | F10: =Data!A9 -> Sullivan, Jessica | G10: =Data!C9 -> 7/12/1984 | H10: =Data!H9 -> 44644 | I10: =Data!I9 -> 3/25/2022 | J10: =Data!J9 -> 302.4 | K10: =TODAY()-I10 -> 55 | L10: =Data!M9 -> 0 | M10: Select Status | N10: =VLOOKUP(M10,Table1[#All],3,FALSE) -> Note | O10: =VLOOKUP(M10,Table1[#All],4,FALSE) -> Q1 | Q10: =VLOOKUP(M10,Table1[#All],5,FALSE) -> Q2 | S10: =VLOOKUP(M10,Table1[#All],6,FALSE) -> Q3 | U10: =VLOOKUP(M10,Table1[#All],7,FALSE) -> Q4 | W10: =VLOOKUP(M10,Table1[#All],8,FALSE) -> Q5 | Y10: =VLOOKUP(M10,Table1[#All],2,FALSE) -> Action | Z10: =VLOOKUP(M10,Table1[#All],9,FALSE) -> Additional Notes: | AC10: Select | AD10: Select | AG10: Select
A11: =Data!K10 -> Cigna | B11: =Data!L10 -> 8002446224 | C11: =Data!D10 -> Sullivan, Carter | D11: =Data!F10 -> U47262786 | E11: =Data!B10 -> 2668 | F11: =Data!A10 -> Sullivan, Carter | G11: =Data!C10 -> 7/12/1984 | H11: =Data!H10 -> 44643 | I11: =Data!I10 -> 3/24/2022 | J11: =Data!J10 -> 102 | K11: =TODAY()-I11 -> 56 | L11: =Data!M10 -> 0 | M11: Select Status | N11: =VLOOKUP(M11,Table1[#All],3,FALSE) -> Note | O11: =VLOOKUP(M11,Table1[#All],4,FALSE) -> Q1 | Q11: =VLOOKUP(M11,Table1[#All],5,FALSE) -> Q2 | S11: =VLOOKUP(M11,Table1[#All],6,FALSE) -> Q3 | U11: =VLOOKUP(M11,Table1[#All],7,FALSE) -> Q4 | W11: =VLOOKUP(M11,Table1[#All],8,FALSE) -> Q5 | Y11: =VLOOKUP(M11,Table1[#All],2,FALSE) -> Action | Z11: =VLOOKUP(M11,Table1[#All],9,FALSE) -> Additional Notes: | AC11: Select | AD11: Select | AG11: Select
A12: =Data!K11 -> Cigna | B12: =Data!L11 -> 8002446224 | C12: =Data!D11 -> Arthur, Bernika | D12: =Data!F11 -> U49852743 | E12: =Data!B11 -> 3727 | F12: =Data!A11 -> Arthur, Bernika | G12: =Data!C11 -> 8/26/1988 | H12: =Data!H11 -> 44639 | I12: =Data!I11 -> 3/21/2022 | J12: =Data!J11 -> 123.6 | K12: =TODAY()-I12 -> 59 | L12: =Data!M11 -> 0 | M12: Select Status | N12: =VLOOKUP(M12,Table1[#All],3,FALSE) -> Note | O12: =VLOOKUP(M12,Table1[#All],4,FALSE) -> Q1 | Q12: =VLOOKUP(M12,Table1[#All],5,FALSE) -> Q2 | S12: =VLOOKUP(M12,Table1[#All],6,FALSE) -> Q3 | U12: =VLOOKUP(M12,Table1[#All],7,FALSE) -> Q4 | W12: =VLOOKUP(M12,Table1[#All],8,FALSE) -> Q5 | Y12: =VLOOKUP(M12,Table1[#All],2,FALSE) -> Action | Z12: =VLOOKUP(M12,Table1[#All],9,FALSE) -> Additional Notes: | AC12: Select | AD12: Select | AG12: Select
A13: =Data!K12 -> Cigna | B13: =Data!L12 -> 8002446224 | C13: =Data!D12 -> Arthur, Lilyana | D13: =Data!F12 -> U49852743 | E13: =Data!B12 -> 3729 | F13: =Data!A12 -> Arthur, Lilyana | G13: =Data!C12 -> 8/26/1988 | H13: =Data!H12 -> 44639 | I13: =Data!I12 -> 3/21/2022 | J13: =Data!J12 -> 58.8 | K13: =TODAY()-I13 -> 59 | L13: =Data!M12 -> 0 | M13: Select Status | N13: =VLOOKUP(M13,Table1[#All],3,FALSE) -> Note | O13: =VLOOKUP(M13,Table1[#All],4,FALSE) -> Q1 | Q13: =VLOOKUP(M13,Table1[#All],5,FALSE) -> Q2 | S13: =VLOOKUP(M13,Table1[#All],6,FALSE) -> Q3 | U13: =VLOOKUP(M13,Table1[#All],7,FALSE) -> Q4 | W13: =VLOOKUP(M13,Table1[#All],8,FALSE) -> Q5 | Y13: =VLOOKUP(M13,Table1[#All],2,FALSE) -> Action | Z13: =VLOOKUP(M13,Table1[#All],9,FALSE) -> Additional Notes: | AC13: Select | AD13: Select | AG13: Select
A14: =Data!K13 -> Cigna | B14: =Data!L13 -> 8002446224 | C14: =Data!D13 -> Arthur, Lilyana | D14: =Data!F13 -> U49852743 | E14: =Data!B13 -> 3729 | F14: =Data!A13 -> Arthur, Lilyana | G14: =Data!C13 -> 8/26/1988 | H14: =Data!H13 -> 44639 | I14: =Data!I13 -> 3/21/2022 | J14: =Data!J13 -> 79.2 | K14: =TODAY()-I14 -> 59 | L14: =Data!M13 -> 0 | M14: Select Status | N14: =VLOOKUP(M14,Table1[#All],3,FALSE) -> Note | O14: =VLOOKUP(M14,Table1[#All],4,FALSE) -> Q1 | Q14: =VLOOKUP(M14,Table1[#All],5,FALSE) -> Q2 | S14: =VLOOKUP(M14,Table1[#All],6,FALSE) -> Q3 | U14: =VLOOKUP(M14,Table1[#All],7,FALSE) -> Q4 | W14: =VLOOKUP(M14,Table1[#All],8,FALSE) -> Q5 | Y14: =VLOOKUP(M14,Table1[#All],2,FALSE) -> Action | Z14: =VLOOKUP(M14,Table1[#All],9,FALSE) -> Additional Notes: | AC14: Select | AD14: Select | AG14: Select
A15: =Data!K14 -> Cigna | B15: =Data!L14 -> 8002446224 | C15: =Data!D14 -> Belle , Byron | D15: =Data!F14 -> U72051724 | E15: =Data!B14 -> 4246 | F15: =Data!A14 -> Belle , Byron | G15: =Data!C14 -> 6/10/1992 | H15: =Data!H14 -> 44573 | I15: =Data!I14 -> 1/13/2022 | J15: =Data!J14 -> 266 | K15: =TODAY()-I15 -> 126 | L15: =Data!M14 -> 0 | M15: CLAIM PAID - EFT | N15: =VLOOKUP(M15,Table1[#All],3,FALSE) -> Claim Paid by EFT; | O15: =VLOOKUP(M15,Table1[#All],4,FALSE) -> Issue Date: | P15: 44580 | Q15: =VLOOKUP(M15,Table1[#All],5,FALSE) -> EFT# | R15: 9999761864 | S15: =VLOOKUP(M15,Table1[#All],6,FALSE) -> Bulk/Sep: | T15: single | U15: =VLOOKUP(M15,Table1[#All],7,FALSE) -> Call Ref#: | V15: 2763 | W15: =VLOOKUP(M15,Table1[#All],8,FALSE) -> Cust Rep: | X15: MJ | Y15: =VLOOKUP(M15,Table1[#All],2,FALSE) -> Task Post Pmt Queue | Z15: =VLOOKUP(M15,Table1[#All],9,FALSE) -> Additional Notes: | AA15: Rep State that Code D0120, D0220, D0230 & (Partially) D0274 are applied towards the deductable. D1208 - denied due to Age limit (Age limit under 19) Rep Name: Moises, Call Ref: 4641//Rep States that the Claim Paid,Claim No:D220146565680, paid amt$130 Patient Resp: $136. | AB15: CLAIM CLOSED | AC15: YES | AD15: V Team | AE15: AA | AF15: 44664 | AG15: Follow-Up Complete
A16: =Data!K15 -> Cigna | B16: =Data!L15 -> 8002446224 | C16: =Data!D15 -> Arthur, Devin | D16: =Data!F15 -> U49852743 | E16: =Data!B15 -> 3728 | F16: =Data!A15 -> Arthur, Devin | G16: =Data!C15 -> 8/26/1988 | H16: =Data!H15 -> 44478 | I16: =Data!I15 -> 10/11/2021 | J16: =Data!J15 -> 230 | K16: =TODAY()-I16 -> 220 | L16: =Data!M15 -> 0 | M16: CLAIM PAID - EFT | N16: =VLOOKUP(M16,Table1[#All],3,FALSE) -> Claim Paid by EFT; | O16: =VLOOKUP(M16,Table1[#All],4,FALSE) -> Issue Date: | P16: 44481 | Q16: =VLOOKUP(M16,Table1[#All],5,FALSE) -> EFT# | R16: 9997740967 | S16: =VLOOKUP(M16,Table1[#All],6,FALSE) -> Bulk/Sep: | T16: Bulk | U16: =VLOOKUP(M16,Table1[#All],7,FALSE) -> Call Ref#: | V16: 9764 | W16: =VLOOKUP(M16,Table1[#All],8,FALSE) -> Cust Rep: | X16: sara | Y16: =VLOOKUP(M16,Table1[#All],2,FALSE) -> Task Post Pmt Queue | Z16: =VLOOKUP(M16,Table1[#All],9,FALSE) -> Additional Notes: | AA16: Rep States that Claim Paid,Claim No:D212856143800, paid amt$113 Patient Resp: NIL, All the lines paid on the claim. | AB16: NV pending | AC16: YES | AD16: V Team | AE16: MU | AF16: 44607 | AG16: Follow-Up Complete
A17: =Data!K16 -> Cigna | B17: =Data!L16 -> 8002446224 | C17: =Data!D16 -> Arthur, Bernika | D17: =Data!F16 -> U49852743 | E17: =Data!B16 -> 3727 | F17: =Data!A16 -> Arthur, Bernika | G17: =Data!C16 -> 8/26/1988 | H17: =Data!H16 -> 44478 | I17: =Data!I16 -> 10/11/2021 | J17: =Data!J16 -> 216 | K17: =TODAY()-I17 -> 220 | L17: =Data!M16 -> 0 | M17: CLAIM PAID - EFT | N17: =VLOOKUP(M17,Table1[#All],3,FALSE) -> Claim Paid by EFT; | O17: =VLOOKUP(M17,Table1[#All],4,FALSE) -> Issue Date: | P17: 44482 | Q17: =VLOOKUP(M17,Table1[#All],5,FALSE) -> EFT# | R17: 9997740967 | S17: =VLOOKUP(M17,Table1[#All],6,FALSE) -> Bulk/Sep: | T17: Single | U17: =VLOOKUP(M17,Table1[#All],7,FALSE) -> Call Ref#: | V17: 5334 | W17: =VLOOKUP(M17,Table1[#All],8,FALSE) -> Cust Rep: | X17: Nel | Y17: =VLOOKUP(M17,Table1[#All],2,FALSE) -> Task Post Pmt Queue | Z17: =VLOOKUP(M17,Table1[#All],9,FALSE) -> Additional Notes: | AA17: Pd $4.00 Pt res $76.00 Clm #D212856144410 was cashed on 10/18/2021 | AB17: NV pending | AC17: YES | AD17: V Team | AE17: DK | AF17: 44579 | AG17: Follow-Up Complete
A18: =Data!K17 -> Cigna | B18: =Data!L17 -> 8002446224 | C18: =Data!D17 -> Rasmussen , John | D18: =Data!F17 -> U153667756 | E18: =Data!B17 -> 6734 | F18: =Data!A17 -> Rasmussen , John | G18: =Data!C17 -> 9/25/1954 | H18: =Data!H17 -> 44474 | I18: =Data!I17 -> 10/7/2021 | J18: =Data!J17 -> 88.8 | K18: =TODAY()-I18 -> 224 | L18: =Data!M17 -> 0 | M18: CLAIM PAID - EFT | N18: =VLOOKUP(M18,Table1[#All],3,FALSE) -> Claim Paid by EFT; | O18: =VLOOKUP(M18,Table1[#All],4,FALSE) -> Issue Date: | P18: 44477 | Q18: =VLOOKUP(M18,Table1[#All],5,FALSE) -> EFT# | R18: 9997740965 | S18: =VLOOKUP(M18,Table1[#All],6,FALSE) -> Bulk/Sep: | T18: SEP | U18: =VLOOKUP(M18,Table1[#All],7,FALSE) -> Call Ref#: | V18: 7209 | W18: =VLOOKUP(M18,Table1[#All],8,FALSE) -> Cust Rep: | X18: Erick | Y18: =VLOOKUP(M18,Table1[#All],2,FALSE) -> Task Post Pmt Queue | Z18: =VLOOKUP(M18,Table1[#All],9,FALSE) -> Additional Notes: | AA18: Rep States that Claim Paid,Claim No:R212816304340,Pd Amt $53; Patient Resp: Nil, | AB18: NV pending | AC18: YES | AD18: V Team | AE18: AA | AF18: 44585 | AG18: Follow-Up Complete
A19: =Data!K18 -> Cigna | B19: =Data!L18 -> 8002446224 | C19: =Data!D18 -> Knight, Richard | D19: =Data!F18 -> U72076261 | E19: =Data!B18 -> 5453 | F19: =Data!A18 -> Knight, Richard | G19: =Data!C18 -> 5/5/1970 | H19: =Data!H18 -> 44322 | I19: =Data!I18 -> 5/6/2021 | J19: =Data!J18 -> 890 | K19: =TODAY()-I19 -> 378 | L19: =Data!M18 -> 0 | M19: DENIED - MORE INFO | N19: =VLOOKUP(M19,Table1[#All],3,FALSE) -> Ins needs more info, need to submit; | O19: =VLOOKUP(M19,Table1[#All],4,FALSE) -> Attachments/Info needed? | P19: Prep Date,Seat Date & Initial or Replacement Prior Placement Date | Q19: =VLOOKUP(M19,Table1[#All],5,FALSE) -> Fax # (If Fax Yes): | R19: 8595502662 | S19: =VLOOKUP(M19,Table1[#All],6,FALSE) -> Call Ref#: | T19: 7991 | U19: =VLOOKUP(M19,Table1[#All],7,FALSE) -> Cust Rep: | V19: Michal | W19: =VLOOKUP(M19,Table1[#All],8,FALSE) -> 0 | Y19: =VLOOKUP(M19,Table1[#All],2,FALSE) -> Task Sub Pending Claims Queue | Z19: =VLOOKUP(M19,Table1[#All],9,FALSE) -> Additional Notes: | AA19: Rep State Clm Denied,Claim No: S211306181710,Mailing Address: PO Box 188037. Chattanooga, TN 37422,TFL: 365 Days for Out of Nework Patient,Processed & Denied Date: 07/19/2021 | AB19: NV pending | AC19: NO | AD19: V Team | AE19: AA | AF19: 44655 | AG19: Follow-Up Complete
A20: =Data!K19 -> Cigna Out Of Network | B20: =Data!L19 -> 8004486262 | C20: =Data!D19 -> Mokry, Lila | D20: =Data!F19 -> u34464213 | E20: =Data!B19 -> 7171 | F20: =Data!A19 -> Mokry, Lila | G20: =Data!C19 -> 8/15/2016 | H20: =Data!H19 -> 44343 | I20: =Data!I19 -> 6/2/2021 | J20: =Data!J19 -> 256.4 | K20: =TODAY()-I20 -> 351 | L20: =Data!M19 -> 0 | M20: CNOF Active | N20: =VLOOKUP(M20,Table1[#All],3,FALSE) -> Claim not on file. Patient is active ; | O20: =VLOOKUP(M20,Table1[#All],4,FALSE) -> Payor ID & Address: | P20: 62308 | Q20: =VLOOKUP(M20,Table1[#All],5,FALSE) -> Fax # (If Fax Yes): | R20: 8595502662 | S20: =VLOOKUP(M20,Table1[#All],6,FALSE) -> TFL in Mnths: | T20: No Limit | U20: =VLOOKUP(M20,Table1[#All],7,FALSE) -> Call Ref#: | V20: 1606 | W20: =VLOOKUP(M20,Table1[#All],8,FALSE) -> Cust Rep: | X20: Irvin | Y20: =VLOOKUP(M20,Table1[#All],2,FALSE) -> Task Sub Pending Claims Queue | Z20: =VLOOKUP(M20,Table1[#All],9,FALSE) -> Additional Notes: | AA20: Claim Resubmitted electronically on 05/06/2022 - SN // Rep State that CNOF,Effective Date:01/01/2021, Mailing Adrss: P.O.BOX 188037,Chattanooga,TN 37422 Rep Name: Michal Call Ref: 1569 | AB20: 44701 | AC20: NO | AD20: V Team | AE20: AA | AF20: 44655 | AG20: Further Follow-Up
A21: =Data!K20 -> Cigna | B21: =Data!L20 -> 8002446224 | C21: =Data!D20 -> Johnson , Alina | D21: =Data!F20 -> U26438292 | E21: =Data!B20 -> 5823 | F21: =Data!A20 -> Johnson , Alina | G21: =Data!C20 -> 11/19/1975 | H21: =Data!H20 -> 44643 | I21: =Data!I20 -> 3/24/2022 | J21: =Data!J20 -> 496 | K21: =TODAY()-I21 -> 56 | L21: =Data!M20 -> 0 | M21: Select Status | N21: =VLOOKUP(M21,Table1[#All],3,FALSE) -> Note | O21: =VLOOKUP(M21,Table1[#All],4,FALSE) -> Q1 | Q21: =VLOOKUP(M21,Table1[#All],5,FALSE) -> Q2 | S21: =VLOOKUP(M21,Table1[#All],6,FALSE) -> Q3 | U21: =VLOOKUP(M21,Table1[#All],7,FALSE) -> Q4 | W21: =VLOOKUP(M21,Table1[#All],8,FALSE) -> Q5 | Y21: =VLOOKUP(M21,Table1[#All],2,FALSE) -> Action | Z21: =VLOOKUP(M21,Table1[#All],9,FALSE) -> Additional Notes: | AC21: Select | AD21: Select | AG21: Select
A22: =Data!K21 -> Cigna | B22: =Data!L21 -> 8002446224 | C22: =Data!D21 -> Johnson, Aila | D22: =Data!F21 -> U26438292 | E22: =Data!B21 -> 9036 | F22: =Data!A21 -> Johnson, Aila | G22: =Data!C21 -> 11/19/1975 | H22: =Data!H21 -> 44643 | I22: =Data!I21 -> 3/24/2022 | J22: =Data!J21 -> 396 | K22: =TODAY()-I22 -> 56 | L22: =Data!M21 -> 0 | M22: Select Status | N22: =VLOOKUP(M22,Table1[#All],3,FALSE) -> Note | O22: =VLOOKUP(M22,Table1[#All],4,FALSE) -> Q1 | Q22: =VLOOKUP(M22,Table1[#All],5,FALSE) -> Q2 | S22: =VLOOKUP(M22,Table1[#All],6,FALSE) -> Q3 | U22: =VLOOKUP(M22,Table1[#All],7,FALSE) -> Q4 | W22: =VLOOKUP(M22,Table1[#All],8,FALSE) -> Q5 | Y22: =VLOOKUP(M22,Table1[#All],2,FALSE) -> Action | Z22: =VLOOKUP(M22,Table1[#All],9,FALSE) -> Additional Notes: | AC22: Select | AD22: Select | AG22: Select
A23: =Data!K22 -> Cigna | B23: =Data!L22 -> 8002446224 | C23: =Data!D22 -> Kienia, Jaxon | D23: =Data!F22 -> U53657370 | E23: =Data!B22 -> 7711 | F23: =Data!A22 -> Kienia, Jaxon | G23: =Data!C22 -> 12/2/1990 | H23: =Data!H22 -> 44636 | I23: =Data!I22 -> 3/17/2022 | J23: =Data!J22 -> 940 | K23: =TODAY()-I23 -> 63 | L23: =Data!M22 -> 0 | M23: Select Status | N23: =VLOOKUP(M23,Table1[#All],3,FALSE) -> Note | O23: =VLOOKUP(M23,Table1[#All],4,FALSE) -> Q1 | Q23: =VLOOKUP(M23,Table1[#All],5,FALSE) -> Q2 | S23: =VLOOKUP(M23,Table1[#All],6,FALSE) -> Q3 | U23: =VLOOKUP(M23,Table1[#All],7,FALSE) -> Q4 | W23: =VLOOKUP(M23,Table1[#All],8,FALSE) -> Q5 | Y23: =VLOOKUP(M23,Table1[#All],2,FALSE) -> Action | Z23: =VLOOKUP(M23,Table1[#All],9,FALSE) -> Additional Notes: | AC23: Select | AD23: Select | AG23: Select
A24: =Data!K23 -> Cigna | B24: =Data!L23 -> 8002446224 | C24: =Data!D23 -> Michaelis, Benjamin | D24: =Data!F23 -> U50621274 | E24: =Data!B23 -> 8777 | F24: =Data!A23 -> Michaelis, Benjamin | G24: =Data!C23 -> 12/13/1986 | H24: =Data!H23 -> 44630 | I24: =Data!I23 -> 3/11/2022 | J24: =Data!J23 -> 1062 | K24: =TODAY()-I24 -> 69 | L24: =Data!M23 -> 0 | M24: Select Status | N24: =VLOOKUP(M24,Table1[#All],3,FALSE) -> Note | O24: =VLOOKUP(M24,Table1[#All],4,FALSE) -> Q1 | Q24: =VLOOKUP(M24,Table1[#All],5,FALSE) -> Q2 | S24: =VLOOKUP(M24,Table1[#All],6,FALSE) -> Q3 | U24: =VLOOKUP(M24,Table1[#All],7,FALSE) -> Q4 | W24: =VLOOKUP(M24,Table1[#All],8,FALSE) -> Q5 | Y24: =VLOOKUP(M24,Table1[#All],2,FALSE) -> Action | Z24: =VLOOKUP(M24,Table1[#All],9,FALSE) -> Additional Notes: | AC24: Select | AD24: Select | AG24: Select
A25: =Data!K24 -> Cigna | B25: =Data!L24 -> 8002446224 | C25: =Data!D24 -> Salgado, Manuel | D25: =Data!F24 -> U52668717 | E25: =Data!B24 -> 9237 | F25: =Data!A24 -> Salgado, Manuel | G25: =Data!C24 -> 10/30/1993 | H25: =Data!H24 -> 44630 | I25: =Data!I24 -> 3/11/2022 | J25: =Data!J24 -> 256.4 | K25: =TODAY()-I25 -> 69 | L25: =Data!M24 -> 0 | M25: Select Status | N25: =VLOOKUP(M25,Table1[#All],3,FALSE) -> Note | O25: =VLOOKUP(M25,Table1[#All],4,FALSE) -> Q1 | Q25: =VLOOKUP(M25,Table1[#All],5,FALSE) -> Q2 | S25: =VLOOKUP(M25,Table1[#All],6,FALSE) -> Q3 | U25: =VLOOKUP(M25,Table1[#All],7,FALSE) -> Q4 | W25: =VLOOKUP(M25,Table1[#All],8,FALSE) -> Q5 | Y25: =VLOOKUP(M25,Table1[#All],2,FALSE) -> Action | Z25: =VLOOKUP(M25,Table1[#All],9,FALSE) -> Additional Notes: | AC25: Select | AD25: Select | AG25: Select
A26: =Data!K25 -> Cigna | B26: =Data!L25 -> 8002446224 | C26: =Data!D25 -> Cox, Racheal | D26: =Data!F25 -> U7550053602 | E26: =Data!B25 -> 7471 | F26: =Data!A25 -> Cox, Racheal | G26: =Data!C25 -> 11/27/1996 | H26: =Data!H25 -> 44384 | I26: =Data!I25 -> 3/7/2022 | J26: =Data!J25 -> 820.8 | K26: =TODAY()-I26 -> 73 | L26: =Data!M25 -> 0 | M26: Select Status | N26: =VLOOKUP(M26,Table1[#All],3,FALSE) -> Note | O26: =VLOOKUP(M26,Table1[#All],4,FALSE) -> Q1 | Q26: =VLOOKUP(M26,Table1[#All],5,FALSE) -> Q2 | S26: =VLOOKUP(M26,Table1[#All],6,FALSE) -> Q3 | U26: =VLOOKUP(M26,Table1[#All],7,FALSE) -> Q4 | W26: =VLOOKUP(M26,Table1[#All],8,FALSE) -> Q5 | Y26: =VLOOKUP(M26,Table1[#All],2,FALSE) -> Action | Z26: =VLOOKUP(M26,Table1[#All],9,FALSE) -> Additional Notes: | AC26: Select | AD26: Select | AG26: Select
A27: =Data!K26 -> Cigna | B27: =Data!L26 -> 8002446224 | C27: =Data!D26 -> Sexton Free , Brittney | D27: =Data!F26 -> u65208005 | E27: =Data!B26 -> 5759 | F27: =Data!A26 -> Sexton Free , Brittney | G27: =Data!C26 -> 11/9/1994 | H27: =Data!H26 -> 44624 | I27: =Data!I26 -> 3/7/2022 | J27: =Data!J26 -> 1315.2 | K27: =TODAY()-I27 -> 73 | L27: =Data!M26 -> 0 | M27: Select Status | N27: =VLOOKUP(M27,Table1[#All],3,FALSE) -> Note | O27: =VLOOKUP(M27,Table1[#All],4,FALSE) -> Q1 | Q27: =VLOOKUP(M27,Table1[#All],5,FALSE) -> Q2 | S27: =VLOOKUP(M27,Table1[#All],6,FALSE) -> Q3 | U27: =VLOOKUP(M27,Table1[#All],7,FALSE) -> Q4 | W27: =VLOOKUP(M27,Table1[#All],8,FALSE) -> Q5 | Y27: =VLOOKUP(M27,Table1[#All],2,FALSE) -> Action | Z27: =VLOOKUP(M27,Table1[#All],9,FALSE) -> Additional Notes: | AC27: Select | AD27: Select | AG27: Select
A28: =Data!K27 -> Cigna | B28: =Data!L27 -> 8002446224 | C28: =Data!D27 -> Sexton Free , Brittney | D28: =Data!F27 -> u65208005 | E28: =Data!B27 -> 5759 | F28: =Data!A27 -> Sexton Free , Brittney | G28: =Data!C27 -> 11/9/1994 | H28: =Data!H27 -> 44601 | I28: =Data!I27 -> 2/10/2022 | J28: =Data!J27 -> 253.2 | K28: =TODAY()-I28 -> 98 | L28: =Data!M27 -> 0 | M28: DENIED - NOT COVERED | N28: =VLOOKUP(M28,Table1[#All],3,FALSE) -> Procedure is not a covered benefit; | O28: =VLOOKUP(M28,Table1[#All],4,FALSE) -> Why? | P28: Not covered under pt plan | Q28: =VLOOKUP(M28,Table1[#All],5,FALSE) -> Call Ref#: | R28: 1142 | S28: =VLOOKUP(M28,Table1[#All],6,FALSE) -> Cust Rep: | T28: RHEA | U28: =VLOOKUP(M28,Table1[#All],7,FALSE) -> 0 | W28: =VLOOKUP(M28,Table1[#All],8,FALSE) -> 0 | Y28: =VLOOKUP(M28,Table1[#All],2,FALSE) -> Task Client - Denied Claim Queue | Z28: =VLOOKUP(M28,Table1[#All],9,FALSE) -> Additional Notes: | AA28: CLM#D22042654574,Processed Date: 02/11/2022,Your plan does not provide benefits for this service,Patient Resp: $253.20 | AB28: L2 Pending | AC28: YES | AD28: V Team | AE28: AA | AF28: 44698 | AG28: EOB Downloaded
A29: =Data!K28 -> Cigna | B29: =Data!L28 -> 8002446224 | C29: =Data!D28 -> Sexton Free , Brittney | D29: =Data!F28 -> u65208005 | E29: =Data!B28 -> 5759 | F29: =Data!A28 -> Sexton Free , Brittney | G29: =Data!C28 -> 11/9/1994 | H29: =Data!H28 -> 44573 | I29: =Data!I28 -> 1/17/2022 | J29: =Data!J28 -> 210 | K29: =TODAY()-I29 -> 122 | L29: =Data!M28 -> 0 | M29: CLAIM PAID - EFT | N29: =VLOOKUP(M29,Table1[#All],3,FALSE) -> Claim Paid by EFT; | O29: =VLOOKUP(M29,Table1[#All],4,FALSE) -> Issue Date: | P29: 44580 | Q29: =VLOOKUP(M29,Table1[#All],5,FALSE) -> EFT# | R29: 9999730907 | S29: =VLOOKUP(M29,Table1[#All],6,FALSE) -> Bulk/Sep: | T29: Bulk | U29: =VLOOKUP(M29,Table1[#All],7,FALSE) -> Call Ref#: | V29: 83827 | W29: =VLOOKUP(M29,Table1[#All],8,FALSE) -> Cust Rep: | X29: Mabby | Y29: =VLOOKUP(M29,Table1[#All],2,FALSE) -> Task Post Pmt Queue | Z29: =VLOOKUP(M29,Table1[#All],9,FALSE) -> Additional Notes: | AA29: Rep States that Claim Paid,Claim No:E220186079630,Patient Resp: NIL. | AB29: CLAIM CLOSED | AC29: YES | AD29: V Team | AE29: MA | AF29: 44606 | AG29: Follow-Up Complete
A30: =Data!K29 -> Cigna | B30: =Data!L29 -> 8002446224 | C30: =Data!D29 -> Gibson, Karl | D30: =Data!F29 -> U39194271 | E30: =Data!B29 -> 8803 | F30: =Data!A29 -> Gibson, Karl | G30: =Data!C29 -> 4/7/1988 | H30: =Data!H29 -> 44575 | I30: =Data!I29 -> 1/17/2022 | J30: =Data!J29 -> 294.8 | K30: =TODAY()-I30 -> 122 | L30: =Data!M29 -> 0 | M30: CLAIM PAID - EFT | N30: =VLOOKUP(M30,Table1[#All],3,FALSE) -> Claim Paid by EFT; | O30: =VLOOKUP(M30,Table1[#All],4,FALSE) -> Issue Date: | P30: 44580 | Q30: =VLOOKUP(M30,Table1[#All],5,FALSE) -> EFT# | R30: 9999761865 | S30: =VLOOKUP(M30,Table1[#All],6,FALSE) -> Bulk/Sep: | T30: Bulk | U30: =VLOOKUP(M30,Table1[#All],7,FALSE) -> Call Ref#: | V30: 7994 | W30: =VLOOKUP(M30,Table1[#All],8,FALSE) -> Cust Rep: | X30: Mabby | Y30: =VLOOKUP(M30,Table1[#All],2,FALSE) -> Task Post Pmt Queue | Z30: =VLOOKUP(M30,Table1[#All],9,FALSE) -> Additional Notes: | AA30: Rep States that Claim Paid,Claim No:S220186079630,Patient Resp: NIL All the lines paid on the claim. | AB30: CLAIM CLOSED | AC30: YES | AD30: V Team | AE30: MA | AF30: 44606 | AG30: Follow-Up Complete
A31: =Data!K30 -> Cigna | B31: =Data!L30 -> 8002446224 | C31: =Data!D30 -> Huston, Olivia | D31: =Data!F30 -> U39194271 | E31: =Data!B30 -> 8802 | F31: =Data!A30 -> Huston, Olivia | G31: =Data!C30 -> 4/7/1988 | H31: =Data!H30 -> 44575 | I31: =Data!I30 -> 1/17/2022 | J31: =Data!J30 -> 256.4 | K31: =TODAY()-I31 -> 122 | L31: =Data!M30 -> 0 | M31: CNOF Active | N31: =VLOOKUP(M31,Table1[#All],3,FALSE) -> Claim not on file. Patient is active ; | O31: =VLOOKUP(M31,Table1[#All],4,FALSE) -> Payor ID & Address: | P31: 62308 | Q31: =VLOOKUP(M31,Table1[#All],5,FALSE) -> Fax # (If Fax Yes): | R31: 8595502662 | S31: =VLOOKUP(M31,Table1[#All],6,FALSE) -> TFL in Mnths: | T31: No Limit | U31: =VLOOKUP(M31,Table1[#All],7,FALSE) -> Call Ref#: | V31: 6550 | W31: =VLOOKUP(M31,Table1[#All],8,FALSE) -> Cust Rep: | X31: Mabby | Y31: =VLOOKUP(M31,Table1[#All],2,FALSE) -> Task Sub Pending Claims Queue | Z31: =VLOOKUP(M31,Table1[#All],9,FALSE) -> Additional Notes: | AA31: Claim Resubmitted through fax on 05/06/2022 - SN // Rep states that clm is not on file for the dos, the patient is active, we can send send the clm through fax #8595502662, NO TFL. | AB31: 44701 | AC31: NO | AD31: V Team | AE31: DK | AF31: 44606 | AG31: Further Follow-Up
A32: =Data!K31 -> Cigna | B32: =Data!L31 -> 8002446224 | C32: =Data!D31 -> Michaelis, Benjamin | D32: =Data!F31 -> U50621274 | E32: =Data!B31 -> 8777 | F32: =Data!A31 -> Michaelis, Benjamin | G32: =Data!C31 -> 12/13/1986 | H32: =Data!H31 -> 44566 | I32: =Data!I31 -> 1/12/2022 | J32: =Data!J31 -> 186 | K32: =TODAY()-I32 -> 127 | L32: =Data!M31 -> 0 | M32: CLAIM PAID - EFT | N32: =VLOOKUP(M32,Table1[#All],3,FALSE) -> Claim Paid by EFT; | O32: =VLOOKUP(M32,Table1[#All],4,FALSE) -> Issue Date: | P32: 44575 | Q32: =VLOOKUP(M32,Table1[#All],5,FALSE) -> EFT# | R32: 9999761866 | S32: =VLOOKUP(M32,Table1[#All],6,FALSE) -> Bulk/Sep: | T32: bulk | U32: =VLOOKUP(M32,Table1[#All],7,FALSE) -> Call Ref#: | V32: 5749 | W32: =VLOOKUP(M32,Table1[#All],8,FALSE) -> Cust Rep: | X32: Joei | Y32: =VLOOKUP(M32,Table1[#All],2,FALSE) -> Task Post Pmt Queue | Z32: =VLOOKUP(M32,Table1[#All],9,FALSE) -> Additional Notes: | AA32: Rep States that Claim Paid,Paid Amt: 123.20,Claim No:E220146565650,Patient Resp:$62.80 All the lines paid on the claim. | AB32: NV pending | AC32: YES | AD32: V Team | AE32: AA | AF32: 44663 | AG32: Follow-Up Complete
A33: =Data!K32 -> Cigna | B33: =Data!L32 -> 8002446224 | C33: =Data!D32 -> Delk, Mark | D33: =Data!F32 -> U62450847 | E33: =Data!B32 -> 8713 | F33: =Data!A32 -> Delk, Mark | G33: =Data!C32 -> 7/1/1961 | H33: =Data!H32 -> 44557 | I33: =Data!I32 -> 12/30/2021 | J33: =Data!J32 -> 372.8 | K33: =TODAY()-I33 -> 140 | L33: =Data!M32 -> 0 | M33: CLAIM PAID - EFT | N33: =VLOOKUP(M33,Table1[#All],3,FALSE) -> Claim Paid by EFT; | O33: =VLOOKUP(M33,Table1[#All],4,FALSE) -> Issue Date: | P33: 44561 | Q33: =VLOOKUP(M33,Table1[#All],5,FALSE) -> EFT# | R33: 9999367367 | S33: =VLOOKUP(M33,Table1[#All],6,FALSE) -> Bulk/Sep: | T33: Sep | U33: =VLOOKUP(M33,Table1[#All],7,FALSE) -> Call Ref#: | V33: 4651 | W33: =VLOOKUP(M33,Table1[#All],8,FALSE) -> Cust Rep: | X33: natalie | Y33: =VLOOKUP(M33,Table1[#All],2,FALSE) -> Task Post Pmt Queue | Z33: =VLOOKUP(M33,Table1[#All],9,FALSE) -> Additional Notes: | AA33: Rep states that, Claim paid EFT Mode. Cashed out 01/05/2022 for $320.40. Rep name: NICs. Ref# 8666. Claim# E213656187000.//EOB Requested 24 Hr as per Rep Rep Name: Michal Call Ref: 1569//GET EOB -SN // Rep States that the Claim Paid,Claim No:E21365618700, paid amt$320.40 Patient Resp: $52.40 | AB33: NV pending | AC33: YES | AD33: V Team | AE33: SF//SN | AF33: 44655 | AG33: Follow-Up Complete
A34: =Data!K33 -> Cigna | B34: =Data!L33 -> 8002446224 | C34: =Data!D33 -> Ramsey, Jerod | D34: =Data!F33 -> U69059849 | E34: =Data!B33 -> 8165 | F34: =Data!A33 -> Ramsey, Jerod | G34: =Data!C33 -> 4/11/1992 | H34: =Data!H33 -> 44477 | I34: =Data!I33 -> 10/11/2021 | J34: =Data!J33 -> 244.8 | K34: =TODAY()-I34 -> 220 | L34: =Data!M33 -> 0 | M34: CLAIM PAID - EFT | N34: =VLOOKUP(M34,Table1[#All],3,FALSE) -> Claim Paid by EFT; | O34: =VLOOKUP(M34,Table1[#All],4,FALSE) -> Issue Date: | P34: 44482 | Q34: =VLOOKUP(M34,Table1[#All],5,FALSE) -> EFT# | R34: 9997740966 | S34: =VLOOKUP(M34,Table1[#All],6,FALSE) -> Bulk/Sep: | T34: Single | U34: =VLOOKUP(M34,Table1[#All],7,FALSE) -> Call Ref#: | V34: 5422 | W34: =VLOOKUP(M34,Table1[#All],8,FALSE) -> Cust Rep: | X34: Ey | Y34: =VLOOKUP(M34,Table1[#All],2,FALSE) -> Task Post Pmt Queue | Z34: =VLOOKUP(M34,Table1[#All],9,FALSE) -> Additional Notes: | AA34: Pd $105 Pt responsibility $'0' Clm #D212856143770. All codes are got paid. Eob requested | AB34: CLAIM CLOSED | AC34: YES | AD34: V Team | AE34: DK | AF34: 44579 | AG34: Follow-Up Complete
A35: =Data!K34 -> Cigna | B35: =Data!L34 -> 8002446224 | C35: =Data!D34 -> Kienia, Brooke | D35: =Data!F34 -> U53657370 | E35: =Data!B34 -> 7712 | F35: =Data!A34 -> Kienia, Brooke | G35: =Data!C34 -> 12/2/1990 | H35: =Data!H34 -> 44426 | I35: =Data!I34 -> 8/27/2021 | J35: =Data!J34 -> 273.2 | K35: =TODAY()-I35 -> 265 | L35: =Data!M34 -> 0 | M35: CLAIM PAID - EFT | N35: =VLOOKUP(M35,Table1[#All],3,FALSE) -> Claim Paid by EFT; | O35: =VLOOKUP(M35,Table1[#All],4,FALSE) -> Issue Date: | P35: 44438 | Q35: =VLOOKUP(M35,Table1[#All],5,FALSE) -> EFT# | R35: 128408296 | S35: =VLOOKUP(M35,Table1[#All],6,FALSE) -> Bulk/Sep: | T35: Bulk | U35: =VLOOKUP(M35,Table1[#All],7,FALSE) -> Call Ref#: | V35: 7115 | W35: =VLOOKUP(M35,Table1[#All],8,FALSE) -> Cust Rep: | X35: Roger | Y35: =VLOOKUP(M35,Table1[#All],2,FALSE) -> Task Post Pmt Queue | Z35: =VLOOKUP(M35,Table1[#All],9,FALSE) -> Additional Notes: | AA35: Rep States that Claim Paid,Claim No:E212426363940, paid amt$124 Patient Resp: NIL, All the lines paid on the claim. | AB35: CLAIM CLOSED | AC35: YES | AD35: V Team | AE35: MA | AF35: 44614 | AG35: Follow-Up Complete
A36: =Data!K35 -> Cigna | B36: =Data!L35 -> 8002446224 | C36: =Data!D35 -> Kienia, Jaxon | D36: =Data!F35 -> U53657370 | E36: =Data!B35 -> 7711 | F36: =Data!A35 -> Kienia, Jaxon | G36: =Data!C35 -> 12/2/1990 | H36: =Data!H35 -> 44426 | I36: =Data!I35 -> 8/27/2021 | J36: =Data!J35 -> 256.4 | K36: =TODAY()-I36 -> 265 | L36: =Data!M35 -> 0 | M36: CLAIM PAID - EFT | N36: =VLOOKUP(M36,Table1[#All],3,FALSE) -> Claim Paid by EFT; | O36: =VLOOKUP(M36,Table1[#All],4,FALSE) -> Issue Date: | P36: 44438 | Q36: =VLOOKUP(M36,Table1[#All],5,FALSE) -> EFT# | R36: 9996836027 | S36: =VLOOKUP(M36,Table1[#All],6,FALSE) -> Bulk/Sep: | T36: Bulk | U36: =VLOOKUP(M36,Table1[#All],7,FALSE) -> Call Ref#: | V36: 9985 | W36: =VLOOKUP(M36,Table1[#All],8,FALSE) -> Cust Rep: | X36: sara | Y36: =VLOOKUP(M36,Table1[#All],2,FALSE) -> Task Post Pmt Queue | Z36: =VLOOKUP(M36,Table1[#All],9,FALSE) -> Additional Notes: | AA36: EOB Requested//Get EOB - SN // Rep States that the Claim Paid,Claim No:D212426363980, paid amt$114 , All the lines paid on the claim. | AB36: CLAIM CLOSED | AC36: NO | AD36: V Team | AE36: AA | AF36: 2/28/2022 & 04/29/2022 | AG36: Follow-Up Complete
A37: =Data!K36 -> Cigna | B37: =Data!L36 -> 8002446224 | C37: =Data!D36 -> Al-Jehani, Afton | D37: =Data!F36 -> U50782273 | E37: =Data!B36 -> 7755 | F37: =Data!A36 -> Al-Jehani, Afton | G37: =Data!C36 -> 5/10/1992 | H37: =Data!H36 -> 44425 | I37: =Data!I36 -> 8/27/2021 | J37: =Data!J36 -> 325.2 | K37: =TODAY()-I37 -> 265 | L37: =Data!M36 -> 0 | M37: CLAIM PAID - EFT | N37: =VLOOKUP(M37,Table1[#All],3,FALSE) -> Claim Paid by EFT; | O37: =VLOOKUP(M37,Table1[#All],4,FALSE) -> Issue Date: | P37: 44439 | Q37: =VLOOKUP(M37,Table1[#All],5,FALSE) -> EFT# | R37: 6836028 | S37: =VLOOKUP(M37,Table1[#All],6,FALSE) -> Bulk/Sep: | T37: Single | U37: =VLOOKUP(M37,Table1[#All],7,FALSE) -> Call Ref#: | V37: 3545 | W37: =VLOOKUP(M37,Table1[#All],8,FALSE) -> Cust Rep: | X37: karissa | Y37: =VLOOKUP(M37,Table1[#All],2,FALSE) -> Task Post Pmt Queue | Z37: =VLOOKUP(M37,Table1[#All],9,FALSE) -> Additional Notes: | AA37: Pd $105 Pt responsibility $47.00 Clm #E2124726363920. All codes are got paid. Eob requested | AB37: CLAIM CLOSED | AC37: YES | AD37: V Team | AE37: DK | AF37: 44569 | AG37: Follow-Up Complete
A38: =Data!K37 -> DELTA DENTAL OF IOWA | B38: =Data!L37 -> 8005440718 | C38: =Data!D37 -> SHERMAN, STEPHANIE | D38: =Data!F37 -> 3199644 | E38: =Data!B37 -> 3523 | F38: =Data!A37 -> SHERMAN, STEPHANIE | G38: =Data!C37 -> 5/20/1977 | H38: =Data!H37 -> 44265 | I38: =Data!I37 -> 4/15/2021 | J38: =Data!J37 -> 230 | K38: =TODAY()-I38 -> 399 | L38: =Data!M37 -> 0 | M38: CLAIM PAID - EFT | N38: =VLOOKUP(M38,Table1[#All],3,FALSE) -> Claim Paid by EFT; | O38: =VLOOKUP(M38,Table1[#All],4,FALSE) -> Issue Date: | P38: 44321 | Q38: =VLOOKUP(M38,Table1[#All],5,FALSE) -> EFT# | R38: 921050501590 | S38: =VLOOKUP(M38,Table1[#All],6,FALSE) -> Bulk/Sep: | T38: Bulk | U38: =VLOOKUP(M38,Table1[#All],7,FALSE) -> Call Ref#: | V38: 021720211010 | W38: =VLOOKUP(M38,Table1[#All],8,FALSE) -> Cust Rep: | X38: jane | Y38: =VLOOKUP(M38,Table1[#All],2,FALSE) -> Task Post Pmt Queue | Z38: =VLOOKUP(M38,Table1[#All],9,FALSE) -> Additional Notes: | AA38: Rep states that the clm#202110611427-1 total amt$181 Pt resp paid on the Nil. | AB38: NV pending | AC38: YES | AD38: V Team | AE38: SN | AF38: 44609 | AG38: Follow-Up Complete
A39: =Data!K38 -> DELTA DENTAL OF MICHIGAN | B39: =Data!L38 -> 8005240149 | C39: =Data!D38 -> Tamsen , Robin | D39: =Data!F38 -> 394847319 | E39: =Data!B38 -> 5758 | F39: =Data!A38 -> Tamsen , Robin | G39: =Data!C38 -> 0 | H39: =Data!H38 -> 44498 | I39: =Data!I38 -> 12/11/2021 | J39: =Data!J38 -> 593.2 | K39: =TODAY()-I39 -> 159 | L39: =Data!M38 -> 0 | M39: PRTL - PAID EFT | N39: =VLOOKUP(M39,Table1[#All],3,FALSE) -> Claim Partially Paid by EFT; Add notes | O39: =VLOOKUP(M39,Table1[#All],4,FALSE) -> Issue Date: | P39: 44658 | Q39: =VLOOKUP(M39,Table1[#All],5,FALSE) -> EFT# | R39: 9907646801 | S39: =VLOOKUP(M39,Table1[#All],6,FALSE) -> Bulk/Sep: | T39: Sep | U39: =VLOOKUP(M39,Table1[#All],7,FALSE) -> Call Ref#: | V39: 2001833603 | W39: =VLOOKUP(M39,Table1[#All],8,FALSE) -> Cust Rep: | X39: Musheerah | Y39: =VLOOKUP(M39,Table1[#All],2,FALSE) -> Task Post Pmt Queue | Z39: =VLOOKUP(M39,Table1[#All],9,FALSE) -> Additional Notes: | AA39: Rep State Clm No:2111102306400,Paid Amt: 190.50,Patient Resp 292.50 Code D9230 is denied as it is not covered //Rep states that claim has been sent for reprosessing and the EOB has sent to the provideers mailing address. Rep Santo id #2001261703. ///REWORK & UPDATE - SN // Rep states that the clm #2112142747268, the claim is on hold because the ins is wondering that the member has the sec policy with him, there is a DPOW-CCHP is the sec policy for the patient, Rep says that we have to submitt with only the primay insurance policy which is Delta dental to allow the benifits of the claim. | AB39: 44698 | AC39: NO | AD39: V Team | AE39: AA | AF39: 44665 | AG39: Further Follow-Up
A40: =Data!K39 -> Delta Dental of Minnesota | B40: =Data!L39 -> 8004483815 | C40: =Data!D39 -> Tweedt, David | D40: =Data!F39 -> 916435131 | E40: =Data!B39 -> 8109 | F40: =Data!A39 -> Tweedt, David | G40: =Data!C39 -> 10/8/1961 | H40: =Data!H39 -> 44617 | I40: =Data!I39 -> 2/25/2022 | J40: =Data!J39 -> 890 | K40: =TODAY()-I40 -> 83 | L40: =Data!M39 -> 0 | M40: Select Status | N40: =VLOOKUP(M40,Table1[#All],3,FALSE) -> Note | O40: =VLOOKUP(M40,Table1[#All],4,FALSE) -> Q1 | Q40: =VLOOKUP(M40,Table1[#All],5,FALSE) -> Q2 | S40: =VLOOKUP(M40,Table1[#All],6,FALSE) -> Q3 | U40: =VLOOKUP(M40,Table1[#All],7,FALSE) -> Q4 | W40: =VLOOKUP(M40,Table1[#All],8,FALSE) -> Q5 | Y40: =VLOOKUP(M40,Table1[#All],2,FALSE) -> Action | Z40: =VLOOKUP(M40,Table1[#All],9,FALSE) -> Additional Notes: | AC40: Select | AD40: Select | AG40: Select
...

Sheet Level 2
D1: Total No of Claims ===================================> | E1: ='Summary '!C27 -> 1065 | F1: =COUNTIF(E5:E1200,"Task Created") -> 16 | G1: <==========================Task Created
A2: TASK TEMPLATE | D2: INSB NV Team Pending Tasks ===========> | E2: =COUNTIF(E5:E1200,"INSB NV Team Task ") -> 216 | F2: =COUNTIF(E5:E1200,"Further Follow-Up") -> 0 | G2: <==========================Further Followup
D3: Closed (Task Created + Resolved =======================> | E3: =COUNTIF(E5:E1200,"Claim Resolved ")+COUNTIF(E5:E1200,"Task Created") -> 32
A4: Task Subject | B4: Task Detail | C4: Action | D4: What We Need/Reason (Tasking to Client) | E4: Claim Status | F4: Completed By | G4: Level 2 Comment
A5: =CONCATENATE("Pt Id:",'Level 1'!E5," ","Pt Name: ",'Level 1'!F5," ","DOS: ", TEXT('Level 1'!H5,"mm-dd-yyyy")," "," Amnt: ","$",'Level 1'!J5," ", 'Level 1'!N5) -> Pt Id:9200 Pt Name: Passehl , Kayla DOS: 03-15-2022 Amnt: $292.4 Note | B5: =CONCATENATE("Detail: ",'Level 1'!N5," ",'Level 1'!O5,TEXT('Level 1'!P5," mm-dd-yyyy"),";"," ",'Level 1'!Q5,'Level 1'!R5," ",'Level 1'!T5," ","Payment "," ",'Level 1'!U5," ",'Level 1'!V5," ",'Level 1'!W5," ",'Level 1'!X5," ",'Level 1'!Z5, " ",'Level 1'!AA5, " ","Insurance: ",'Level 1'!A5) -> Detail: Note Q1 01-00-1900; Q2 Payment Q4 Q5 Additional Notes: Insurance: Aetna | C5: ='Level 1'!Y5 -> Action | D5: =VLOOKUP(C5,Table2[#All],3,FALSE) -> What we need from you/Reason | E5: Claim Status
A6: =CONCATENATE("Pt Id:",'Level 1'!E6," ","Pt Name: ",'Level 1'!F6," ","DOS: ", TEXT('Level 1'!H6,"mm-dd-yyyy")," "," Amnt: ","$",'Level 1'!J6," ", 'Level 1'!N6) -> Pt Id:7412 Pt Name: Brown, Isabella DOS: 10-01-2021 Amnt: $1036.8 Claim Paid by Check; | B6: =CONCATENATE("Detail: ",'Level 1'!N6," ",'Level 1'!O6,TEXT('Level 1'!P6," mm-dd-yyyy"),";"," ",'Level 1'!Q6,'Level 1'!R6," ",'Level 1'!T6," ","Payment "," ",'Level 1'!U6," ",'Level 1'!V6," ",'Level 1'!W6," ",'Level 1'!X6," ",'Level 1'!Z6, " ",'Level 1'!AA6, " ","Insurance: ",'Level 1'!A6) -> Detail: Claim Paid by Check; Issue Date: 10-15-2021; CHK#237237308 Single Payment Call Ref#: 2070 Cust Rep: Poni Additional Notes: Rep states that clm #043444672190, paid amt $702.40, Its is a V.C.C payment and the draft number #237237308, patient responsibility is 303.60. cashed dt 10/26/2021. Insurance: Ameritas | C6: ='Level 1'!Y6 -> Task Cashed Chk Queue | D6: =VLOOKUP(C6,Table2[#All],3,FALSE) -> What We Need From You: Please confirm Check was received. Reason: To close claim. | E6: Task Created | F6: MU
A7: =CONCATENATE("Pt Id:",'Level 1'!E7," ","Pt Name: ",'Level 1'!F7," ","DOS: ", TEXT('Level 1'!H7,"mm-dd-yyyy")," "," Amnt: ","$",'Level 1'!J7," ", 'Level 1'!N7) -> Pt Id:9330 Pt Name: Thom, Keri DOS: 03-22-2022 Amnt: $294.8 Note | B7: =CONCATENATE("Detail: ",'Level 1'!N7," ",'Level 1'!O7,TEXT('Level 1'!P7," mm-dd-yyyy"),";"," ",'Level 1'!Q7,'Level 1'!R7," ",'Level 1'!T7," ","Payment "," ",'Level 1'!U7," ",'Level 1'!V7," ",'Level 1'!W7," ",'Level 1'!X7," ",'Level 1'!Z7, " ",'Level 1'!AA7, " ","Insurance: ",'Level 1'!A7) -> Detail: Note Q1 01-00-1900; Q2 Payment Q4 Q5 Additional Notes: Insurance: Anthem | C7: ='Level 1'!Y7 -> Action | D7: =VLOOKUP(C7,Table2[#All],3,FALSE) -> What we need from you/Reason | E7: Claim Status
A8: =CONCATENATE("Pt Id:",'Level 1'!E8," ","Pt Name: ",'Level 1'!F8," ","DOS: ", TEXT('Level 1'!H8,"mm-dd-yyyy")," "," Amnt: ","$",'Level 1'!J8," ", 'Level 1'!N8) -> Pt Id:4527 Pt Name: Wricks, Derrishia DOS: 12-15-2021 Amnt: $266 Claim not on file. Patient is active ; | B8: =CONCATENATE("Detail: ",'Level 1'!N8," ",'Level 1'!O8,TEXT('Level 1'!P8," mm-dd-yyyy"),";"," ",'Level 1'!Q8,'Level 1'!R8," ",'Level 1'!T8," ","Payment "," ",'Level 1'!U8," ",'Level 1'!V8," ",'Level 1'!W8," ",'Level 1'!X8," ",'Level 1'!Z8, " ",'Level 1'!AA8, " ","Insurance: ",'Level 1'!A8) -> Detail: Claim not on file. Patient is active ; Payor ID & Address:CB950; Fax # (If Fax Yes): 12Months from Dos Payment Call Ref#: LEANDRO Cust Rep: 8719609 Additional Notes: CNOF - Active Insurance: Anthem | C8: ='Level 1'!Y8 -> Task Sub Pending Claims Queue | D8: =VLOOKUP(C8,Table2[#All],3,FALSE) -> N/A | E8: INSB NV Team Task | F8: SN
A9: =CONCATENATE("Pt Id:",'Level 1'!E9," ","Pt Name: ",'Level 1'!F9," ","DOS: ", TEXT('Level 1'!H9,"mm-dd-yyyy")," "," Amnt: ","$",'Level 1'!J9," ", 'Level 1'!N9) -> Pt Id:8543 Pt Name: Allen, Janiyah DOS: 12-15-2021 Amnt: $307.2 Claim not on file. Patient is active ; | B9: =CONCATENATE("Detail: ",'Level 1'!N9," ",'Level 1'!O9,TEXT('Level 1'!P9," mm-dd-yyyy"),";"," ",'Level 1'!Q9,'Level 1'!R9," ",'Level 1'!T9," ","Payment "," ",'Level 1'!U9," ",'Level 1'!V9," ",'Level 1'!W9," ",'Level 1'!X9," ",'Level 1'!Z9, " ",'Level 1'!AA9, " ","Insurance: ",'Level 1'!A9) -> Detail: Claim not on file. Patient is active ; Payor ID & Address:CB950; Fax # (If Fax Yes): 12 Months from Dos Payment Call Ref#: 87214304 Cust Rep: CELLE Additional Notes: CNOF - Active. Insurance: Anthem | C9: ='Level 1'!Y9 -> Task Sub Pending Claims Queue | D9: =VLOOKUP(C9,Table2[#All],3,FALSE) -> N/A | E9: INSB NV Team Task | F9: SN
A10: =CONCATENATE("Pt Id:",'Level 1'!E10," ","Pt Name: ",'Level 1'!F10," ","DOS: ", TEXT('Level 1'!H10,"mm-dd-yyyy")," "," Amnt: ","$",'Level 1'!J10," ", 'Level 1'!N10) -> Pt Id:9345 Pt Name: Sullivan, Jessica DOS: 03-24-2022 Amnt: $302.4 Note | B10: =CONCATENATE("Detail: ",'Level 1'!N10," ",'Level 1'!O10,TEXT('Level 1'!P10," mm-dd-yyyy"),";"," ",'Level 1'!Q10,'Level 1'!R10," ",'Level 1'!T10," ","Payment "," ",'Level 1'!U10," ",'Level 1'!V10," ",'Level 1'!W10," ",'Level 1'!X10," ",'Level 1'!Z10, " ",'Level 1'!AA10, " ","Insurance: ",'Level 1'!A10) -> Detail: Note Q1 01-00-1900; Q2 Payment Q4 Q5 Additional Notes: Insurance: Cigna | C10: ='Level 1'!Y10 -> Action | D10: =VLOOKUP(C10,Table2[#All],3,FALSE) -> What we need from you/Reason | E10: Claim Status
A11: =CONCATENATE("Pt Id:",'Level 1'!E11," ","Pt Name: ",'Level 1'!F11," ","DOS: ", TEXT('Level 1'!H11,"mm-dd-yyyy")," "," Amnt: ","$",'Level 1'!J11," ", 'Level 1'!N11) -> Pt Id:2668 Pt Name: Sullivan, Carter DOS: 03-23-2022 Amnt: $102 Note | B11: =CONCATENATE("Detail: ",'Level 1'!N11," ",'Level 1'!O11,TEXT('Level 1'!P11," mm-dd-yyyy"),";"," ",'Level 1'!Q11,'Level 1'!R11," ",'Level 1'!T11," ","Payment "," ",'Level 1'!U11," ",'Level 1'!V11," ",'Level 1'!W11," ",'Level 1'!X11," ",'Level 1'!Z11, " ",'Level 1'!AA11, " ","Insurance: ",'Level 1'!A11) -> Detail: Note Q1 01-00-1900; Q2 Payment Q4 Q5 Additional Notes: Insurance: Cigna | C11: ='Level 1'!Y11 -> Action | D11: =VLOOKUP(C11,Table2[#All],3,FALSE) -> What we need from you/Reason | E11: Claim Status
A12: =CONCATENATE("Pt Id:",'Level 1'!E12," ","Pt Name: ",'Level 1'!F12," ","DOS: ", TEXT('Level 1'!H12,"mm-dd-yyyy")," "," Amnt: ","$",'Level 1'!J12," ", 'Level 1'!N12) -> Pt Id:3727 Pt Name: Arthur, Bernika DOS: 03-19-2022 Amnt: $123.6 Note | B12: =CONCATENATE("Detail: ",'Level 1'!N12," ",'Level 1'!O12,TEXT('Level 1'!P12," mm-dd-yyyy"),";"," ",'Level 1'!Q12,'Level 1'!R12," ",'Level 1'!T12," ","Payment "," ",'Level 1'!U12," ",'Level 1'!V12," ",'Level 1'!W12," ",'Level 1'!X12," ",'Level 1'!Z12, " ",'Level 1'!AA12, " ","Insurance: ",'Level 1'!A12) -> Detail: Note Q1 01-00-1900; Q2 Payment Q4 Q5 Additional Notes: Insurance: Cigna | C12: ='Level 1'!Y12 -> Action | D12: =VLOOKUP(C12,Table2[#All],3,FALSE) -> What we need from you/Reason | E12: Claim Status
A13: =CONCATENATE("Pt Id:",'Level 1'!E13," ","Pt Name: ",'Level 1'!F13," ","DOS: ", TEXT('Level 1'!H13,"mm-dd-yyyy")," "," Amnt: ","$",'Level 1'!J13," ", 'Level 1'!N13) -> Pt Id:3729 Pt Name: Arthur, Lilyana DOS: 03-19-2022 Amnt: $58.8 Note | B13: =CONCATENATE("Detail: ",'Level 1'!N13," ",'Level 1'!O13,TEXT('Level 1'!P13," mm-dd-yyyy"),";"," ",'Level 1'!Q13,'Level 1'!R13," ",'Level 1'!T13," ","Payment "," ",'Level 1'!U13," ",'Level 1'!V13," ",'Level 1'!W13," ",'Level 1'!X13," ",'Level 1'!Z13, " ",'Level 1'!AA13, " ","Insurance: ",'Level 1'!A13) -> Detail: Note Q1 01-00-1900; Q2 Payment Q4 Q5 Additional Notes: Insurance: Cigna | C13: ='Level 1'!Y13 -> Action | D13: =VLOOKUP(C13,Table2[#All],3,FALSE) -> What we need from you/Reason | E13: Claim Status
A14: =CONCATENATE("Pt Id:",'Level 1'!E14," ","Pt Name: ",'Level 1'!F14," ","DOS: ", TEXT('Level 1'!H14,"mm-dd-yyyy")," "," Amnt: ","$",'Level 1'!J14," ", 'Level 1'!N14) -> Pt Id:3729 Pt Name: Arthur, Lilyana DOS: 03-19-2022 Amnt: $79.2 Note | B14: =CONCATENATE("Detail: ",'Level 1'!N14," ",'Level 1'!O14,TEXT('Level 1'!P14," mm-dd-yyyy"),";"," ",'Level 1'!Q14,'Level 1'!R14," ",'Level 1'!T14," ","Payment "," ",'Level 1'!U14," ",'Level 1'!V14," ",'Level 1'!W14," ",'Level 1'!X14," ",'Level 1'!Z14, " ",'Level 1'!AA14, " ","Insurance: ",'Level 1'!A14) -> Detail: Note Q1 01-00-1900; Q2 Payment Q4 Q5 Additional Notes: Insurance: Cigna | C14: ='Level 1'!Y14 -> Action | D14: =VLOOKUP(C14,Table2[#All],3,FALSE) -> What we need from you/Reason | E14: Claim Status
A15: =CONCATENATE("Pt Id:",'Level 1'!E15," ","Pt Name: ",'Level 1'!F15," ","DOS: ", TEXT('Level 1'!H15,"mm-dd-yyyy")," "," Amnt: ","$",'Level 1'!J15," ", 'Level 1'!N15) -> Pt Id:4246 Pt Name: Belle , Byron DOS: 01-12-2022 Amnt: $266 Claim Paid by EFT; | B15: =CONCATENATE("Detail: ",'Level 1'!N15," ",'Level 1'!O15,TEXT('Level 1'!P15," mm-dd-yyyy"),";"," ",'Level 1'!Q15,'Level 1'!R15," ",'Level 1'!T15," ","Payment "," ",'Level 1'!U15," ",'Level 1'!V15," ",'Level 1'!W15," ",'Level 1'!X15," ",'Level 1'!Z15, " ",'Level 1'!AA15, " ","Insurance: ",'Level 1'!A15) -> Detail: Claim Paid by EFT; Issue Date: 01-19-2022; EFT#9999761864 single Payment Call Ref#: 2763 Cust Rep: MJ Additional Notes: Rep State that Code D0120, D0220, D0230 & (Partially) D0274 are applied towards the deductable. D1208 - denied due to Age limit (Age limit under 19) Rep Name: Moises, Call Ref: 4641//Rep States that the Claim Paid,Claim No:D220146565680, paid amt$130 Patient Resp: $136. Insurance: Cigna | C15: ='Level 1'!Y15 -> Task Post Pmt Queue | D15: =VLOOKUP(C15,Table2[#All],3,FALSE) -> N/A | E15: Claim Resolved | F15: SN/MA | G15: Payment Posted on 05.01.2022
A16: =CONCATENATE("Pt Id:",'Level 1'!E16," ","Pt Name: ",'Level 1'!F16," ","DOS: ", TEXT('Level 1'!H16,"mm-dd-yyyy")," "," Amnt: ","$",'Level 1'!J16," ", 'Level 1'!N16) -> Pt Id:3728 Pt Name: Arthur, Devin DOS: 10-09-2021 Amnt: $230 Claim Paid by EFT; | B16: =CONCATENATE("Detail: ",'Level 1'!N16," ",'Level 1'!O16,TEXT('Level 1'!P16," mm-dd-yyyy"),";"," ",'Level 1'!Q16,'Level 1'!R16," ",'Level 1'!T16," ","Payment "," ",'Level 1'!U16," ",'Level 1'!V16," ",'Level 1'!W16," ",'Level 1'!X16," ",'Level 1'!Z16, " ",'Level 1'!AA16, " ","Insurance: ",'Level 1'!A16) -> Detail: Claim Paid by EFT; Issue Date: 10-12-2021; EFT#9997740967 Bulk Payment Call Ref#: 9764 Cust Rep: sara Additional Notes: Rep States that Claim Paid,Claim No:D212856143800, paid amt$113 Patient Resp: NIL, All the lines paid on the claim. Insurance: Cigna | C16: ='Level 1'!Y16 -> Task Post Pmt Queue | D16: =VLOOKUP(C16,Table2[#All],3,FALSE) -> N/A | E16: INSB NV Team Task | F16: SN
A17: =CONCATENATE("Pt Id:",'Level 1'!E17," ","Pt Name: ",'Level 1'!F17," ","DOS: ", TEXT('Level 1'!H17,"mm-dd-yyyy")," "," Amnt: ","$",'Level 1'!J17," ", 'Level 1'!N17) -> Pt Id:3727 Pt Name: Arthur, Bernika DOS: 10-09-2021 Amnt: $216 Claim Paid by EFT; | B17: =CONCATENATE("Detail: ",'Level 1'!N17," ",'Level 1'!O17,TEXT('Level 1'!P17," mm-dd-yyyy"),";"," ",'Level 1'!Q17,'Level 1'!R17," ",'Level 1'!T17," ","Payment "," ",'Level 1'!U17," ",'Level 1'!V17," ",'Level 1'!W17," ",'Level 1'!X17," ",'Level 1'!Z17, " ",'Level 1'!AA17, " ","Insurance: ",'Level 1'!A17) -> Detail: Claim Paid by EFT; Issue Date: 10-13-2021; EFT#9997740967 Single Payment Call Ref#: 5334 Cust Rep: Nel Additional Notes: Pd $4.00 Pt res $76.00 Clm #D212856144410 was cashed on 10/18/2021 Insurance: Cigna | C17: ='Level 1'!Y17 -> Task Post Pmt Queue | D17: =VLOOKUP(C17,Table2[#All],3,FALSE) -> N/A | E17: INSB NV Team Task | F17: SN
A18: =CONCATENATE("Pt Id:",'Level 1'!E18," ","Pt Name: ",'Level 1'!F18," ","DOS: ", TEXT('Level 1'!H18,"mm-dd-yyyy")," "," Amnt: ","$",'Level 1'!J18," ", 'Level 1'!N18) -> Pt Id:6734 Pt Name: Rasmussen , John DOS: 10-05-2021 Amnt: $88.8 Claim Paid by EFT; | B18: =CONCATENATE("Detail: ",'Level 1'!N18," ",'Level 1'!O18,TEXT('Level 1'!P18," mm-dd-yyyy"),";"," ",'Level 1'!Q18,'Level 1'!R18," ",'Level 1'!T18," ","Payment "," ",'Level 1'!U18," ",'Level 1'!V18," ",'Level 1'!W18," ",'Level 1'!X18," ",'Level 1'!Z18, " ",'Level 1'!AA18, " ","Insurance: ",'Level 1'!A18) -> Detail: Claim Paid by EFT; Issue Date: 10-08-2021; EFT#9997740965 SEP Payment Call Ref#: 7209 Cust Rep: Erick Additional Notes: Rep States that Claim Paid,Claim No:R212816304340,Pd Amt $53; Patient Resp: Nil, Insurance: Cigna | C18: ='Level 1'!Y18 -> Task Post Pmt Queue | D18: =VLOOKUP(C18,Table2[#All],3,FALSE) -> N/A | E18: INSB NV Team Task | F18: SN
A19: =CONCATENATE("Pt Id:",'Level 1'!E19," ","Pt Name: ",'Level 1'!F19," ","DOS: ", TEXT('Level 1'!H19,"mm-dd-yyyy")," "," Amnt: ","$",'Level 1'!J19," ", 'Level 1'!N19) -> Pt Id:5453 Pt Name: Knight, Richard DOS: 05-06-2021 Amnt: $890 Ins needs more info, need to submit; | B19: =CONCATENATE("Detail: ",'Level 1'!N19," ",'Level 1'!O19,TEXT('Level 1'!P19," mm-dd-yyyy"),";"," ",'Level 1'!Q19,'Level 1'!R19," ",'Level 1'!T19," ","Payment "," ",'Level 1'!U19," ",'Level 1'!V19," ",'Level 1'!W19," ",'Level 1'!X19," ",'Level 1'!Z19, " ",'Level 1'!AA19, " ","Insurance: ",'Level 1'!A19) -> Detail: Ins needs more info, need to submit; Attachments/Info needed?Prep Date,Seat Date & Initial or Replacement Prior Placement Date; Fax # (If Fax Yes):8595502662 7991 Payment Cust Rep: Michal 0 Additional Notes: Rep State Clm Denied,Claim No: S211306181710,Mailing Address: PO Box 188037. Chattanooga, TN 37422,TFL: 365 Days for Out of Nework Patient,Processed & Denied Date: 07/19/2021 Insurance: Cigna | C19: ='Level 1'!Y19 -> Task Sub Pending Claims Queue | D19: =VLOOKUP(C19,Table2[#All],3,FALSE) -> N/A | E19: INSB NV Team Task | F19: SN
A20: =CONCATENATE("Pt Id:",'Level 1'!E20," ","Pt Name: ",'Level 1'!F20," ","DOS: ", TEXT('Level 1'!H20,"mm-dd-yyyy")," "," Amnt: ","$",'Level 1'!J20," ", 'Level 1'!N20) -> Pt Id:7171 Pt Name: Mokry, Lila DOS: 05-27-2021 Amnt: $256.4 Claim not on file. Patient is active ; | B20: =CONCATENATE("Detail: ",'Level 1'!N20," ",'Level 1'!O20,TEXT('Level 1'!P20," mm-dd-yyyy"),";"," ",'Level 1'!Q20,'Level 1'!R20," ",'Level 1'!T20," ","Payment "," ",'Level 1'!U20," ",'Level 1'!V20," ",'Level 1'!W20," ",'Level 1'!X20," ",'Level 1'!Z20, " ",'Level 1'!AA20, " ","Insurance: ",'Level 1'!A20) -> Detail: Claim not on file. Patient is active ; Payor ID & Address: 08-03-2070; Fax # (If Fax Yes):8595502662 No Limit Payment Call Ref#: 1606 Cust Rep: Irvin Additional Notes: Claim Resubmitted electronically on 05/06/2022 - SN // Rep State that CNOF,Effective Date:01/01/2021, Mailing Adrss: P.O.BOX 188037,Chattanooga,TN 37422 Rep Name: Michal Call Ref: 1569 Insurance: Cigna Out Of Network | C20: ='Level 1'!Y20 -> Task Sub Pending Claims Queue | D20: =VLOOKUP(C20,Table2[#All],3,FALSE) -> N/A | E20: Review in next report | F20: SN/NE | G20: Claim Resubmitted electronically on 05/06/2022
A21: =CONCATENATE("Pt Id:",'Level 1'!E21," ","Pt Name: ",'Level 1'!F21," ","DOS: ", TEXT('Level 1'!H21,"mm-dd-yyyy")," "," Amnt: ","$",'Level 1'!J21," ", 'Level 1'!N21) -> Pt Id:5823 Pt Name: Johnson , Alina DOS: 03-23-2022 Amnt: $496 Note | B21: =CONCATENATE("Detail: ",'Level 1'!N21," ",'Level 1'!O21,TEXT('Level 1'!P21," mm-dd-yyyy"),";"," ",'Level 1'!Q21,'Level 1'!R21," ",'Level 1'!T21," ","Payment "," ",'Level 1'!U21," ",'Level 1'!V21," ",'Level 1'!W21," ",'Level 1'!X21," ",'Level 1'!Z21, " ",'Level 1'!AA21, " ","Insurance: ",'Level 1'!A21) -> Detail: Note Q1 01-00-1900; Q2 Payment Q4 Q5 Additional Notes: Insurance: Cigna | C21: ='Level 1'!Y21 -> Action | D21: =VLOOKUP(C21,Table2[#All],3,FALSE) -> What we need from you/Reason | E21: Claim Status
A22: =CONCATENATE("Pt Id:",'Level 1'!E22," ","Pt Name: ",'Level 1'!F22," ","DOS: ", TEXT('Level 1'!H22,"mm-dd-yyyy")," "," Amnt: ","$",'Level 1'!J22," ", 'Level 1'!N22) -> Pt Id:9036 Pt Name: Johnson, Aila DOS: 03-23-2022 Amnt: $396 Note | B22: =CONCATENATE("Detail: ",'Level 1'!N22," ",'Level 1'!O22,TEXT('Level 1'!P22," mm-dd-yyyy"),";"," ",'Level 1'!Q22,'Level 1'!R22," ",'Level 1'!T22," ","Payment "," ",'Level 1'!U22," ",'Level 1'!V22," ",'Level 1'!W22," ",'Level 1'!X22," ",'Level 1'!Z22, " ",'Level 1'!AA22, " ","Insurance: ",'Level 1'!A22) -> Detail: Note Q1 01-00-1900; Q2 Payment Q4 Q5 Additional Notes: Insurance: Cigna | C22: ='Level 1'!Y22 -> Action | D22: =VLOOKUP(C22,Table2[#All],3,FALSE) -> What we need from you/Reason | E22: Claim Status
A23: =CONCATENATE("Pt Id:",'Level 1'!E23," ","Pt Name: ",'Level 1'!F23," ","DOS: ", TEXT('Level 1'!H23,"mm-dd-yyyy")," "," Amnt: ","$",'Level 1'!J23," ", 'Level 1'!N23) -> Pt Id:7711 Pt Name: Kienia, Jaxon DOS: 03-16-2022 Amnt: $940 Note | B23: =CONCATENATE("Detail: ",'Level 1'!N23," ",'Level 1'!O23,TEXT('Level 1'!P23," mm-dd-yyyy"),";"," ",'Level 1'!Q23,'Level 1'!R23," ",'Level 1'!T23," ","Payment "," ",'Level 1'!U23," ",'Level 1'!V23," ",'Level 1'!W23," ",'Level 1'!X23," ",'Level 1'!Z23, " ",'Level 1'!AA23, " ","Insurance: ",'Level 1'!A23) -> Detail: Note Q1 01-00-1900; Q2 Payment Q4 Q5 Additional Notes: Insurance: Cigna | C23: ='Level 1'!Y23 -> Action | D23: =VLOOKUP(C23,Table2[#All],3,FALSE) -> What we need from you/Reason | E23: Claim Status
